<?xml version='1.0' encoding='utf-8'?>
<robot name="SnekBot">
    <link name="Joint4">
        <inertial>
            <origin xyz="-7.31917079953468e-07 -0.002720965823309811 -0.06094824846597635" rpy="0.0 9.921302603843483e-48 0.0" />
            <mass value="2.170299150249054" />
            <inertia ixx="0.0027369740583502167" iyy="0.0024848909411751404" izz="0.0016684338780074029" ixy="3.1615957201416657e-09" iyz="-0.00013503545039505189" ixz="-2.4536414205745006e-08" />
        </inertial>
        <visual name="Joint4_visual">
            <origin xyz="3.596647202286215e-15 0.4625999999999996 -0.0007379999999927911" rpy="1.5707963267949114 1.2767564783189294e-15 8.326672684699702e-17" />
            <geometry>
                <mesh filename="meshes/Joint4.stl" scale="0.001 0.001 0.001" />
            </geometry>
        </visual>
        <collision name="Joint4_collision">
            <origin xyz="3.596647202286215e-15 0.4625999999999996 -0.0007379999999927911" rpy="1.5707963267949114 1.2767564783189294e-15 8.326672684699702e-17" />
            <geometry>
                <mesh filename="meshes/Joint4.stl" scale="0.001 0.001 0.001" />
            </geometry>
        </collision>
    </link>
    <link name="Joint3">
        <inertial>
            <origin xyz="1.4095052347553083e-07 -0.06948927422346683 -0.1036765010036558" rpy="0.0 -0.0 1.302943823802202e-60" />
            <mass value="6.860254512476634" />
            <inertia ixx="0.04322168904318646" iyy="0.024701649748137336" izz="0.023746903476123016" ixy="1.2762196315046873e-07" iyz="-0.012385996929821124" ixz="1.9820953079882099e-07" />
        </inertial>
        <visual name="Joint3_visual">
            <origin xyz="-1.1449940995334026e-14 -0.07946199999999974 0.2678000000000019" rpy="3.14159265358979 -8.326672684687583e-17 2.7200464103316296e-15" />
            <geometry>
                <mesh filename="meshes/Joint3.stl" scale="0.001 0.001 0.001" />
            </geometry>
        </visual>
        <collision name="Joint3_collision">
            <origin xyz="-1.1449940995334026e-14 -0.07946199999999974 0.2678000000000019" rpy="3.14159265358979 -8.326672684687583e-17 2.7200464103316296e-15" />
            <geometry>
                <mesh filename="meshes/Joint3.stl" scale="0.001 0.001 0.001" />
            </geometry>
        </collision>
    </link>
    <link name="Joint2">
        <inertial>
            <origin xyz="-7.319170719899921e-07 -0.0027209737564369975 -0.060948248465979474" rpy="3.944304526105059e-31 2.8562667779245755e-62 9.723461371658036e-63" />
            <mass value="2.170299150249074" />
            <inertia ixx="0.0027369739646554694" iyy="0.002484890941175248" izz="0.0016684337843118771" ixy="3.0223270633993016e-09" iyz="-0.00013503450489255433" ixz="-2.453641537002849e-08" />
        </inertial>
        <visual name="Joint2_visual">
            <origin xyz="-1.598721155460225e-16 0.2318000000000018 -0.0007380000000009268" rpy="1.5707963267948906 2.720046410331629e-15 4.494350118222054e-30" />
            <geometry>
                <mesh filename="meshes/Joint2.stl" scale="0.001 0.001 0.001" />
            </geometry>
        </visual>
        <collision name="Joint2_collision">
            <origin xyz="-1.598721155460225e-16 0.2318000000000018 -0.0007380000000009268" rpy="1.5707963267948906 2.720046410331629e-15 4.494350118222054e-30" />
            <geometry>
                <mesh filename="meshes/Joint2.stl" scale="0.001 0.001 0.001" />
            </geometry>
        </collision>
    </link>
    <link name="Joint1">
        <inertial>
            <origin xyz="3.744606777828738e-07 0.04699627745454283 -0.0685629731482273" rpy="0.0 -0.0 0.0" />
            <mass value="4.508264373489419" />
            <inertia ixx="0.016620854857406553" iyy="0.0053441181213154994" izz="0.014592584381142786" ixy="-8.382678952684783e-08" iyz="0.0017626733716701998" ixz="1.5732307931698983e-08" />
        </inertial>
        <visual name="Joint1_visual">
            <origin xyz="1.6431300764452317e-16 -0.11640000000000093 -0.04326200000000045" rpy="-1.5707963267948974 1.8873791418627653e-15 -2.7918280473837364e-30" />
            <geometry>
                <mesh filename="meshes/Joint1.stl" scale="0.001 0.001 0.001" />
            </geometry>
        </visual>
        <collision name="Joint1_collision">
            <origin xyz="1.6431300764452317e-16 -0.11640000000000093 -0.04326200000000045" rpy="-1.5707963267948974 1.8873791418627653e-15 -2.7918280473837364e-30" />
            <geometry>
                <mesh filename="meshes/Joint1.stl" scale="0.001 0.001 0.001" />
            </geometry>
        </collision>
    </link>
    <link name="Joint0">
        <inertial>
            <origin xyz="-7.319170712847745e-07 -0.002720973756436303 -0.06094825459578699" rpy="0.0 -0.0 0.0" />
            <mass value="2.1702991502490603" />
            <inertia ixx="0.002736974476887293" iyy="0.002484891453407082" izz="0.0016684337843122705" ixy="3.02232709200435e-09" iyz="-0.00013503500652223816" ixz="-2.4846328416756894e-08" />
        </inertial>
        <visual name="Joint0_visual">
            <origin xyz="2.77623088262075e-17 -0.07946200000000013 0.036200000000001335" rpy="3.141592653589792 -1.0947644252537633e-47 -2.0184719090619762e-47" />
            <geometry>
                <mesh filename="meshes/Joint0.stl" scale="0.001 0.001 0.001" />
            </geometry>
        </visual>
        <collision name="Joint0_collision">
            <origin xyz="2.77623088262075e-17 -0.07946200000000013 0.036200000000001335" rpy="3.141592653589792 -1.0947644252537633e-47 -2.0184719090619762e-47" />
            <geometry>
                <mesh filename="meshes/Joint0.stl" scale="0.001 0.001 0.001" />
            </geometry>
        </collision>
    </link>
    <link name="Base">
        <inertial>
            <origin xyz="-4.1041387313046547e-07 -0.020138795421307955 0.037548882045009294" rpy="0.0 0.0 0.0" />
            <mass value="3.812666297852429" />
            <inertia ixx="0.012229530771495929" iyy="0.0028824086122589583" izz="0.012002916550538374" ixy="-8.788745509914179e-08" iyz="0.0003716725612075657" ixz="6.83863211127327e-10" />
        </inertial>
        <visual name="Base_visual">
            <origin xyz="0.0 0.0 0.0" rpy="0.0 0.0 0.0" />
            <geometry>
                <mesh filename="meshes/Base.stl" scale="0.001 0.001 0.001" />
            </geometry>
        </visual>
        <collision name="Base_collision">
            <origin xyz="0.0 0.0 0.0" rpy="0.0 0.0 0.0" />
            <geometry>
                <mesh filename="meshes/Base.stl" scale="0.001 0.001 0.001" />
            </geometry>
        </collision>
    </link>
    <link name="Joint5">
        <inertial>
            <origin xyz="-0.0025494513129547705 -7.658363454307156e-06 -0.04525477560826317" rpy="0.0 -0.0 -1.1973985901296076e-48" />
            <mass value="1.7334916519714307" />
            <inertia ixx="0.001411860378429108" iyy="0.0014611336500508494" izz="0.0017669596236022677" ixy="-1.053311216446286e-06" iyz="-1.0945239692345873e-06" ixz="1.6911554138108102e-05" />
        </inertial>
        <visual name="Joint5_visual">
            <origin xyz="-2.468165394286884e-14 -0.07946199999998849 0.4987999999999997" rpy="3.1415926535897682 -5.55111512312237e-17 1.2767564783189308e-15" />
            <geometry>
                <mesh filename="meshes/Joint5.stl" scale="0.001 0.001 0.001" />
            </geometry>
        </visual>
        <collision name="Joint5_collision">
            <origin xyz="-2.468165394286884e-14 -0.07946199999998849 0.4987999999999997" rpy="3.1415926535897682 -5.55111512312237e-17 1.2767564783189308e-15" />
            <geometry>
                <mesh filename="meshes/Joint5.stl" scale="0.001 0.001 0.001" />
            </geometry>
        </collision>
    </link>
    <joint name="Base_Revolute-0" type="revolute">
        <origin xyz="-5.742377618504593e-17 -0.07946200000000023 0.035" rpy="3.141592653589793 0 0" />
        <parent link="Base" />
        <child link="Joint0" />
        <axis xyz="0 0 1" />
        <limit lower="-2.356194" upper="2.356194" effort="87" velocity="2.175" />
    </joint>
    <joint name="Joint0_Revolute-1" type="revolute">
        <origin xyz="-6.192261280341597e-50 -0.036199999999999996 -0.0802" rpy="-1.5707963267948952 0 0" />
        <parent link="Joint0" />
        <child link="Joint1" />
        <axis xyz="0 0 1" />
        <limit lower="-2.356194" upper="2.356194" effort="87" velocity="2.175" />
    </joint>
    <joint name="Joint1_Revolute-2" type="revolute">
        <origin xyz="7.592786212752303e-33 0.11539999999999996 -0.04400000000000016" rpy="-3.1415926535897922 0 0" />
        <parent link="Joint1" />
        <child link="Joint2" />
        <axis xyz="0 0 1" />
        <limit lower="-2.356194" upper="2.356194" effort="87" velocity="2.175" />
    </joint>
    <joint name="Joint2_Revolute-3" type="revolute">
        <origin xyz="5.123092549358938e-32 -0.036200000000000225 -0.08019999999999991" rpy="-1.570796326794893 0 0" />
        <parent link="Joint2" />
        <child link="Joint3" />
        <axis xyz="0 0 1" />
        <limit lower="-2.356194" upper="2.356194" effort="87" velocity="2.175" />
    </joint>
    <joint name="Joint3_Revolute-4" type="revolute">
        <origin xyz="1.1040657277305825e-14 -0.0802000000000012 -0.19479999999999947" rpy="1.5707963267948506 0 0" />
        <parent link="Joint3" />
        <child link="Joint4" />
        <axis xyz="0 0 1" />
        <limit lower="-2.356194" upper="2.356194" effort="87" velocity="2.175" />
    </joint>
    <joint name="Joint4_Revolute-5" type="revolute">
        <origin xyz="1.8787416067335387e-15 -0.036199999999996846 -0.08020000000000144" rpy="-1.570796326794869 0 0" />
        <parent link="Joint4" />
        <child link="Joint5" />
        <axis xyz="0 0 1" />
        <limit lower="-2.356194" upper="2.356194" effort="87" velocity="2.175" />
    </joint>
</robot>